<mujoco model="panda">
  <compiler angle="radian" meshdir="assets" autolimits="true"/>

  <option integrator="implicitfast"/>

  <default>
    <default class="panda">
      <material specular="0.5" shininess="0.25"/>
      <joint armature="0.1" damping="1" axis="0 0 1" range="-2.8973 2.8973"/>
      <general dyntype="none" biastype="affine" ctrlrange="-2.8973 2.8973" forcerange="-87 87"/>
      <default class="finger">
        <joint axis="0 1 0" type="slide" range="0 0.04"/>
      </default>

      <default class="visual">
        <geom type="mesh" contype="0" conaffinity="0" group="2"/>
      </default>
      <default class="collision">
        <geom type="mesh" group="3"/>
        <default class="fingertip_pad_collision_1">
          <geom type="box" size="0.0085 0.004 0.0085" pos="0 0.0055 0.0445"/>
        </default>
        <default class="fingertip_pad_collision_2">
          <geom type="box" size="0.003 0.002 0.003" pos="0.0055 0.002 0.05"/>
        </default>
        <default class="fingertip_pad_collision_3">
          <geom type="box" size="0.003 0.002 0.003" pos="-0.0055 0.002 0.05"/>
        </default>
        <default class="fingertip_pad_collision_4">
          <geom type="box" size="0.003 0.002 0.0035" pos="0.0055 0.002 0.0395"/>
        </default>
        <default class="fingertip_pad_collision_5">
          <geom type="box" size="0.003 0.002 0.0035" pos="-0.0055 0.002 0.0395"/>
        </default>
      </default>
    </default>
  </default>

  <asset>
    <material class="panda" name="white" rgba="1 1 1 1"/>
    <material class="panda" name="off_white" rgba="0.901961 0.921569 0.929412 1"/>
    <material class="panda" name="black" rgba="0.25 0.25 0.25 1"/>
    <material class="panda" name="green" rgba="0 1 0 1"/>
    <material class="panda" name="light_blue" rgba="0.039216 0.541176 0.780392 1"/>

    <!-- Collision meshes -->
    <mesh name="link0_c" file="link0.stl"/>
    <mesh name="link1_c" file="link1.stl"/>
    <mesh name="link2_c" file="link2.stl"/>
    <mesh name="link3_c" file="link3.stl"/>
    <mesh name="link4_c" file="link4.stl"/>
    <mesh name="link5_c0" file="link5_collision_0.obj"/>
    <mesh name="link5_c1" file="link5_collision_1.obj"/>
    <mesh name="link5_c2" file="link5_collision_2.obj"/>
    <mesh name="link6_c" file="link6.stl"/>
    <mesh name="link7_c" file="link7.stl"/>
    <mesh name="hand_c" file="hand.stl"/>

    <!-- Visual meshes -->
    <mesh file="link0_0.obj"/>
    <mesh file="link0_1.obj"/>
    <mesh file="link0_2.obj"/>
    <mesh file="link0_3.obj"/>
    <mesh file="link0_4.obj"/>
    <mesh file="link0_5.obj"/>
    <mesh file="link0_7.obj"/>
    <mesh file="link0_8.obj"/>
    <mesh file="link0_9.obj"/>
    <mesh file="link0_10.obj"/>
    <mesh file="link0_11.obj"/>
    <mesh file="link1.obj"/>
    <mesh file="link2.obj"/>
    <mesh file="link3_0.obj"/>
    <mesh file="link3_1.obj"/>
    <mesh file="link3_2.obj"/>
    <mesh file="link3_3.obj"/>
    <mesh file="link4_0.obj"/>
    <mesh file="link4_1.obj"/>
    <mesh file="link4_2.obj"/>
    <mesh file="link4_3.obj"/>
    <mesh file="link5_0.obj"/>
    <mesh file="link5_1.obj"/>
    <mesh file="link5_2.obj"/>
    <mesh file="link6_0.obj"/>
    <mesh file="link6_1.obj"/>
    <mesh file="link6_2.obj"/>
    <mesh file="link6_3.obj"/>
    <mesh file="link6_4.obj"/>
    <mesh file="link6_5.obj"/>
    <mesh file="link6_6.obj"/>
    <mesh file="link6_7.obj"/>
    <mesh file="link6_8.obj"/>
    <mesh file="link6_9.obj"/>
    <mesh file="link6_10.obj"/>
    <mesh file="link6_11.obj"/>
    <mesh file="link6_12.obj"/>
    <mesh file="link6_13.obj"/>
    <mesh file="link6_14.obj"/>
    <mesh file="link6_15.obj"/>
    <mesh file="link6_16.obj"/>
    <mesh file="link7_0.obj"/>
    <mesh file="link7_1.obj"/>
    <mesh file="link7_2.obj"/>
    <mesh file="link7_3.obj"/>
    <mesh file="link7_4.obj"/>
    <mesh file="link7_5.obj"/>
    <mesh file="link7_6.obj"/>
    <mesh file="link7_7.obj"/>
    <mesh file="hand_0.obj"/>
    <mesh file="hand_1.obj"/>
    <mesh file="hand_2.obj"/>
    <mesh file="hand_3.obj"/>
    <mesh file="hand_4.obj"/>
    <mesh file="finger_0.obj"/>
    <mesh file="finger_1.obj"/>
  </asset>

  <worldbody>
    <light name="top" pos="0 0 2" mode="trackcom"/>
    <body name="link0" childclass="panda">
      <inertial mass="2.3966" pos="-0.0172 0.0004 0.0745"
        fullinertia="0.009 0.0115 0.0085 0.0 0.002 0.0"/>
      <geom mesh="link0_0" material="off_white" class="visual"/>
      <geom mesh="link0_1" material="black" class="visual"/>
      <geom mesh="link0_2" material="off_white" class="visual"/>
      <geom mesh="link0_3" material="black" class="visual"/>
      <geom mesh="link0_4" material="off_white" class="visual"/>
      <geom mesh="link0_5" material="black" class="visual"/>
      <geom mesh="link0_7" material="white" class="visual"/>
      <geom mesh="link0_8" material="white" class="visual"/>
      <geom mesh="link0_9" material="black" class="visual"/>
      <geom mesh="link0_10" material="off_white" class="visual"/>
      <geom mesh="link0_11" material="white" class="visual"/>
      <geom mesh="link0_c" class="collision"/>
      <body name="link1" pos="0 0 0.333">
        <inertial mass="2.9274653454" pos="0.0000004128 -0.0181251324 -0.0386035970"
          fullinertia="0.023927316485107913 0.0224821613275756 0.006350098258530016 1.3317903455714081e-05 -0.00011404774918616684 -0.0019950320628240115"/>
        <joint name="joint1"/>
        <geom material="white" mesh="link1" class="visual"/>
        <geom mesh="link1_c" class="collision"/>
        <body name="link2" quat="1 -1 0 0">
          <inertial mass="2.9355370338" pos="0.0031828864 -0.0743221644 0.0088146084"
            fullinertia="0.041938946257609425 0.02514514885014724 0.06170214472888839 0.00020257331521090626 0.004077784227179924 -0.0042252158006570156"/>
          <joint name="joint2" range="-1.7628 1.7628"/>
          <geom material="white" mesh="link2" class="visual"/>
          <geom mesh="link2_c" class="collision"/>
          <body name="link3" pos="0 -0.316 0" quat="1 1 0 0">
            <joint name="joint3"/>
            <inertial mass="2.2449013699" pos="0.0407015686 -0.0048200565 -0.0289730823"
              fullinertia="0.02410142547240885 0.01974053266708178 0.019044494482244823 0.002404694559042109 -0.002856269270114313 -0.002104212683891874"/>
            <geom mesh="link3_0" material="white" class="visual"/>
            <geom mesh="link3_1" material="white" class="visual"/>
            <geom mesh="link3_2" material="white" class="visual"/>
            <geom mesh="link3_3" material="black" class="visual"/>
            <geom mesh="link3_c" class="collision"/>
            <body name="link4" pos="0.0825 0 0" quat="1 1 0 0">
              <inertial mass="2.6155955791" pos="-0.0459100965 0.0630492960 -0.0085187868"
                fullinertia="0.03452998321913202 0.028881621933049058 0.04125471171146641 0.01322552265982813 0.01015142998484113 -0.0009762833870704552"/>
              <joint name="joint4" range="-3.0718 -0.0698"/>
              <geom mesh="link4_0" material="white" class="visual"/>
              <geom mesh="link4_1" material="white" class="visual"/>
              <geom mesh="link4_2" material="black" class="visual"/>
              <geom mesh="link4_3" material="white" class="visual"/>
              <geom mesh="link4_c" class="collision"/>
              <body name="link5" pos="-0.0825 0.384 0" quat="1 -1 0 0">
                <inertial mass="2.3271207594" pos="-0.0016039605 0.0292536262 -0.0972965990"
                  fullinertia="0.051610278463662895 0.04787729713371481 0.016423625579357254 -0.005715173387783472 -0.0035673167625872135 0.010673985108535986"/>
                <joint name="joint5"/>
                <geom mesh="link5_0" material="black" class="visual"/>
                <geom mesh="link5_1" material="white" class="visual"/>
                <geom mesh="link5_2" material="white" class="visual"/>
                <geom mesh="link5_c0" class="collision"/>
                <geom mesh="link5_c1" class="collision"/>
                <geom mesh="link5_c2" class="collision"/>
                <body name="link6" quat="1 1 0 0">
                  <inertial mass="1.8170376524" pos="0.0597131221 -0.0410294666 -0.0101692726"
                    fullinertia="0.005412333594383447 0.014058329545509979 0.016080817924212554 0.006193456360285834 0.0014219289306117652 -0.0013140753741120031"/>
                  <joint name="joint6" range="-0.0175 3.7525"/>
                  <geom mesh="link6_0" material="off_white" class="visual"/>
                  <geom mesh="link6_1" material="white" class="visual"/>
                  <geom mesh="link6_2" material="black" class="visual"/>
                  <geom mesh="link6_3" material="white" class="visual"/>
                  <geom mesh="link6_4" material="white" class="visual"/>
                  <geom mesh="link6_5" material="white" class="visual"/>
                  <geom mesh="link6_6" material="white" class="visual"/>
                  <geom mesh="link6_7" material="light_blue" class="visual"/>
                  <geom mesh="link6_8" material="light_blue" class="visual"/>
                  <geom mesh="link6_9" material="black" class="visual"/>
                  <geom mesh="link6_10" material="black" class="visual"/>
                  <geom mesh="link6_11" material="white" class="visual"/>
                  <geom mesh="link6_12" material="green" class="visual"/>
                  <geom mesh="link6_13" material="white" class="visual"/>
                  <geom mesh="link6_14" material="black" class="visual"/>
                  <geom mesh="link6_15" material="black" class="visual"/>
                  <geom mesh="link6_16" material="white" class="visual"/>
                  <geom mesh="link6_c" class="collision"/>
                  <body name="link7" pos="0.088 0 0" quat="1 1 0 0">
                    <inertial mass="0.6271432862" pos="0.0045225817 0.0086261921 -0.0161633251"
                      fullinertia="0.00021092389150104718 0.00017718568002411474 5.993190599659971e-05 -2.433299114461931e-05 4.564480393778983e-05 8.744070223226438e-05"/>
                    <joint name="joint7"/>
                    <geom mesh="link7_0" material="white" class="visual"/>
                    <geom mesh="link7_1" material="black" class="visual"/>
                    <geom mesh="link7_2" material="black" class="visual"/>
                    <geom mesh="link7_3" material="black" class="visual"/>
                    <geom mesh="link7_4" material="black" class="visual"/>
                    <geom mesh="link7_5" material="black" class="visual"/>
                    <geom mesh="link7_6" material="black" class="visual"/>
                    <geom mesh="link7_7" material="white" class="visual"/>
                    <geom mesh="link7_c" class="collision"/>
                    <body name="hand" pos="0 0 0.107" quat="0.9238795 0 0 -0.3826834">
                      <inertial mass="0.73" pos="-0.01 0 0.03" diaginertia="0.001 0.0025 0.0017"/>
                      <geom mesh="hand_0" material="off_white" class="visual"/>
                      <geom mesh="hand_1" material="black" class="visual"/>
                      <geom mesh="hand_2" material="black" class="visual"/>
                      <geom mesh="hand_3" material="white" class="visual"/>
                      <geom mesh="hand_4" material="off_white" class="visual"/>
                      <geom mesh="hand_c" class="collision"/>
                      <body name="left_finger" pos="0 0 0.0584">
                        <inertial mass="0.015" pos="0 0 0" diaginertia="2.375e-6 2.375e-6 7.5e-7"/>
                        <joint name="finger_joint1" class="finger"/>
                        <geom mesh="finger_0" material="off_white" class="visual"/>
                        <geom mesh="finger_1" material="black" class="visual"/>
                        <geom mesh="finger_0" class="collision"/>
                        <geom class="fingertip_pad_collision_1"/>
                        <geom class="fingertip_pad_collision_2"/>
                        <geom class="fingertip_pad_collision_3"/>
                        <geom class="fingertip_pad_collision_4"/>
                        <geom class="fingertip_pad_collision_5"/>
                      </body>
                      <body name="right_finger" pos="0 0 0.0584" quat="0 0 0 1">
                        <inertial mass="0.015" pos="0 0 0" diaginertia="2.375e-6 2.375e-6 7.5e-7"/>
                        <joint name="finger_joint2" class="finger"/>
                        <geom mesh="finger_0" material="off_white" class="visual"/>
                        <geom mesh="finger_1" material="black" class="visual"/>
                        <geom mesh="finger_0" class="collision"/>
                        <geom class="fingertip_pad_collision_1"/>
                        <geom class="fingertip_pad_collision_2"/>
                        <geom class="fingertip_pad_collision_3"/>
                        <geom class="fingertip_pad_collision_4"/>
                        <geom class="fingertip_pad_collision_5"/>
                      </body>
                    </body>
                  </body>
                </body>
              </body>
            </body>
          </body>
        </body>
      </body>
    </body>
  </worldbody>

  <tendon>
    <fixed name="split">
      <joint joint="finger_joint1" coef="0.5"/>
      <joint joint="finger_joint2" coef="0.5"/>
    </fixed>
  </tendon>

  <equality>
    <joint joint1="finger_joint1" joint2="finger_joint2" solimp="0.95 0.99 0.001" solref="0.005 1"/>
  </equality>

  <actuator>
    <motor class="panda" name="actuator1" joint="joint1" ctrlrange="-87 87" gear="1"/>
    <motor class="panda" name="actuator2" joint="joint2" ctrlrange="-87 87" gear="1"/>
    <motor class="panda" name="actuator3" joint="joint3" ctrlrange="-87 87" gear="1"/>
    <motor class="panda" name="actuator4" joint="joint4" ctrlrange="-87 87" gear="1"/>
    <motor class="panda" name="actuator5" joint="joint5" ctrlrange="-12 12" gear="1"/>
    <motor class="panda" name="actuator6" joint="joint6" ctrlrange="-12 12" gear="1"/>
    <motor class="panda" name="actuator7" joint="joint7" ctrlrange="-12 12" gear="1"/>
    <!-- Remap original ctrlrange (0, 0.04) to (0, 255): 0.04 * 100 / 255 = 0.01568627451 -->
    <general class="panda" name="actuator8" tendon="split" forcerange="-100 100" ctrlrange="0 255"
      gainprm="0.01568627451 0 0" biasprm="0 -100 -10"/>
  </actuator>

  <keyframe>
    <key name="home" qpos="0 0 0 -1.57079 0 1.57079 -0.7853 0.04 0.04" ctrl="0 0 0 -1.57079 0 1.57079 -0.7853 255"/>
  </keyframe>

  <contact>
    <exclude body1="link0" body2="link1"/>
  </contact>
</mujoco>
