<?xml version="1.0" encoding="utf-8"?>
<robot name="panda">
  <link name="panda_link0">
    <inertial>
      <origin rpy="0 0 0" xyz="0 0 0.05" />
      <mass value="2.9" />
      <inertia ixx="0.1" ixy="0" ixz="0" iyy="0.1" iyz="0" izz="0.1" />
    </inertial>
    <visual>
      <geometry>
        <mesh filename="meshes/collision/link0.obj" />
      </geometry>
      <material name="panda_white">
        <color rgba="1. 1. 1. 1." />
      </material>
    </visual>
    <collision name="sphere_0">
      <origin xyz="-0.04264544187913825 1.5407439555097887e-33 0.05876872932995867" rpy="0 0 0" />
      <geometry>
        <sphere radius="0.1307842451104378" />
      </geometry>
    </collision>
  </link>
  <link name="panda_link1">
    <inertial>
      <origin rpy="0 0 0" xyz="0 -0.04 -0.05" />
      <mass value="2.7" />
      <inertia ixx="0.1" ixy="0" ixz="0" iyy="0.1" iyz="0" izz="0.1" />
    </inertial>
    <visual>
      <geometry>
        <mesh filename="meshes/visual/link1.obj" />
      </geometry>
      <material name="panda_white" />
    </visual>
    <collision name="sphere_1">
      <origin xyz="-0.00329603508793179 -0.004758557536712712 -0.14359494681883925" rpy="0 0 0" />
      <geometry>
        <sphere radius="0.07280062591276722" />
      </geometry>
    </collision>
    <collision name="sphere_2">
      <origin xyz="3.0814879110195774e-33 -0.05140741099778361 -0.06848852150421364" rpy="0 0 0" />
      <geometry>
        <sphere radius="0.0682510557325601" />
      </geometry>
    </collision>
    <collision name="sphere_3">
      <origin xyz="-1.5407439555097887e-33 -0.053416599845353116 0.0027369018324491234" rpy="0 0 0" />
      <geometry>
        <sphere radius="0.07848912226481501" />
      </geometry>
    </collision>
  </link>
  <joint name="panda_joint1" type="revolute">
    <origin rpy="0 0 0" xyz="0 0 0.333" />
    <parent link="panda_link0" />
    <child link="panda_link1" />
    <axis xyz="0 0 1" />
    <limit effort="87" lower="-2.9671" upper="2.9671" velocity="2.1750" />
  </joint>
  <link name="panda_link2">
    <inertial>
      <origin rpy="0 0 0" xyz="0 -0.04 0.06" />
      <mass value="2.73" />
      <inertia ixx="0.1" ixy="0" ixz="0" iyy="0.1" iyz="0" izz="0.1" />
    </inertial>
    <visual>
      <geometry>
        <mesh filename="meshes/visual/link2.obj" />
      </geometry>
      <material name="panda_white" />
    </visual>
    <collision name="sphere_4">
      <origin xyz="3.0814879110195774e-33 -0.012530056279620339 0.053343630642094825" rpy="0 0 0" />
      <geometry>
        <sphere radius="0.08455346725551376" />
      </geometry>
    </collision>
    <collision name="sphere_5">
      <origin xyz="7.703719777548943e-34 -0.09225737132137751 0.02714614435207296" rpy="0 0 0" />
      <geometry>
        <sphere radius="0.06391004188399964" />
      </geometry>
    </collision>
    <collision name="sphere_6">
      <origin xyz="2.2420775429197073e-44 -0.1455833909923181 -2.0194839173657902e-28" rpy="0 0 0" />
      <geometry>
        <sphere radius="0.07441910797835088" />
      </geometry>
    </collision>
  </link>
  <joint name="panda_joint2" type="revolute">
    <origin rpy="-1.57079632679 0 0" xyz="0 0 0" />
    <parent link="panda_link1" />
    <child link="panda_link2" />
    <axis xyz="0 0 1" />
    <limit effort="87" lower="-1.8326" upper="1.8326" velocity="2.1750" />
  </joint>
  <link name="panda_link3">
    <inertial>
      <origin rpy="0 0 0" xyz="0.01 0.01 -0.05" />
      <mass value="2.04" />
      <inertia ixx="0.1" ixy="0" ixz="0" iyy="0.1" iyz="0" izz="0.1" />
    </inertial>
    <visual>
      <geometry>
        <mesh filename="meshes/visual/link3.obj" />
      </geometry>
      <material name="panda_red">
        <color rgba="1. 1. 1. 1." />
      </material>
    </visual>
    <collision name="sphere_7">
      <origin xyz="-4.484155085839415e-44 2.0194839173657902e-28 -0.07704582181226316" rpy="0 0 0" />
      <geometry>
        <sphere radius="0.07331006988737422" />
      </geometry>
    </collision>
    <collision name="sphere_8">
      <origin xyz="0.0766489645462334 0.04993561383343364 -0.0023434960861522525" rpy="0 0 0" />
      <geometry>
        <sphere radius="0.06885274624313893" />
      </geometry>
    </collision>
  </link>
  <joint name="panda_joint3" type="revolute">
    <origin rpy="1.57079632679 0 0" xyz="0 -0.316 0" />
    <parent link="panda_link2" />
    <child link="panda_link3" />
    <axis xyz="0 0 1" />
    <limit effort="87" lower="-2.9671" upper="2.9671" velocity="2.1750" />
  </joint>
  <link name="panda_link4">
    <inertial>
      <origin rpy="0 0 0" xyz="-0.03 0.03 0.02" />
      <mass value="2.08" />
      <inertia ixx="0.1" ixy="0" ixz="0" iyy="0.1" iyz="0" izz="0.1" />
    </inertial>
    <visual>
      <geometry>
        <mesh filename="meshes/visual/link4.obj" />
      </geometry>
      <material name="panda_white" />
    </visual>
    <collision name="sphere_10">
      <origin xyz="-0.0021053298282842636 1.249000902703301e-16 0.0423011598427999" rpy="0 0 0" />
      <geometry>
        <sphere radius="0.07163288632402866" />
      </geometry>
    </collision>
    <collision name="sphere_11">
      <origin xyz="-0.07616331511303398 0.08219029502199784 -1.6155871338926322e-27" rpy="0 0 0" />
      <geometry>
        <sphere radius="0.0724513972711042" />
      </geometry>
    </collision>
  </link>
  <joint name="panda_joint4" type="revolute">
    <origin rpy="1.57079632679 0 0" xyz="0.0825 0 0" />
    <parent link="panda_link3" />
    <child link="panda_link4" />
    <axis xyz="0 0 1" />
    <limit effort="87" lower="-3.1416" upper="0.0" velocity="2.1750" />
  </joint>
  <link name="panda_link5">
    <inertial>
      <origin rpy="0 0 0" xyz="0 0.04 -0.12" />
      <mass value="3" />
      <inertia ixx="0.1" ixy="0" ixz="0" iyy="0.1" iyz="0" izz="0.1" />
    </inertial>
    <visual>
      <geometry>
        <mesh filename="meshes/visual/link5.obj" />
      </geometry>
      <material name="panda_white" />
    </visual>
    <collision name="sphere_12">
      <origin xyz="1.1102230246251565e-15 0.007064511991036862 -0.22718125150925372" rpy="0 0 0" />
      <geometry>
        <sphere radius="0.07094251745835638" />
      </geometry>
    </collision>
    <collision name="sphere_13">
      <origin xyz="8.881784197001252e-16 0.061308264642684664 -0.16511363579755794" rpy="0 0 0" />
      <geometry>
        <sphere radius="0.051032606805737374" />
      </geometry>
    </collision>
    <collision name="sphere_14">
      <origin xyz="1.1102230246251565e-16 0.0793732567735489 -0.0971360269843477" rpy="0 0 0" />
      <geometry>
        <sphere radius="0.051032606805737374" />
      </geometry>
    </collision>
    <collision name="sphere_15">
      <origin xyz="6.661338147750939e-16 0.07675966620297558 -0.007607335277848182" rpy="0 0 0" />
      <geometry>
        <sphere radius="0.06428511238748351" />
      </geometry>
    </collision>
  </link>
  <joint name="panda_joint5" type="revolute">
    <origin rpy="-1.57079632679 0 0" xyz="-0.0825 0.384 0" />
    <parent link="panda_link4" />
    <child link="panda_link5" />
    <axis xyz="0 0 1" />
    <limit effort="12" lower="-2.9671" upper="2.9671" velocity="2.6100" />
  </joint>
  <link name="panda_link6">
    <inertial>
      <origin rpy="0 0 0" xyz="0.04 0 0" />
      <mass value="1.3" />
      <inertia ixx="0.1" ixy="0" ixz="0" iyy="0.1" iyz="0" izz="0.1" />
    </inertial>
    <visual>
      <geometry>
        <mesh filename="meshes/visual/link6.obj" />
      </geometry>
      <material name="panda_white" />
    </visual>
    <collision name="sphere_16">
      <origin xyz="0.0033125282598865935 1.1102230246251565e-16 0.005344867692600751" rpy="0 0 0" />
      <geometry>
        <sphere radius="0.06382896825832496" />
      </geometry>
    </collision>
    <collision name="sphere_17">
      <origin xyz="0.07675237225680365 0.006625755987907822 7.270142102516845e-27" rpy="0 0 0" />
      <geometry>
        <sphere radius="0.08305383451637069" />
      </geometry>
    </collision>
  </link>
  <joint name="panda_joint6" type="revolute">
    <origin rpy="1.57079632679 0 0" xyz="0 0 0" />
    <parent link="panda_link5" />
    <child link="panda_link6" />
    <axis xyz="0 0 1" />
    <limit effort="12" lower="-0.0873" upper="3.8223" velocity="2.6100" />
  </joint>
  <link name="panda_link7">
    <inertial>
      <origin rpy="0 0 0" xyz="0 0 0.08" />
      <mass value=".2" />
      <inertia ixx="0.1" ixy="0" ixz="0" iyy="0.1" iyz="0" izz="0.1" />
    </inertial>
    <visual>
      <geometry>
        <mesh filename="meshes/collision/link7.obj" />
      </geometry>
      <material name="panda_white" />
    </visual>
    <collision name="sphere_19">
      <origin xyz="0.042278790026198054 0.04168145857363254 0.13237686613150995" rpy="0 0 0" />
      <geometry>
        <sphere radius="0.055" />
      </geometry>
    </collision>
    <collision name="sphere_20">
      <origin xyz="-0.04494584986855721 -0.04435563905836972 0.12956827659030623" rpy="0 0 0" />
      <geometry>
        <sphere radius="0.055" />
      </geometry>
    </collision>
    <collision name="sphere_21">
      <origin xyz="0.026309807468235302 0.02642968640327912 0.08499892704057899" rpy="0 0 0" />
      <geometry>
        <sphere radius="0.057910525380297576" />
      </geometry>
    </collision>
    <collision name="sphere_22">
      <origin xyz="-0.0001897711378314737 4.535692919860207e-05 0.18399534185618593" rpy="0 0 0" />
      <geometry>
        <sphere radius="0.04010074179954789" />
      </geometry>
    </collision>
    <collision name="sphere_23">
      <origin xyz="0.0 0.0 0.1306746" rpy="0 0 0" />
      <geometry>
        <sphere radius="0.056992" />
      </geometry>
    </collision>
  </link>
  <joint name="panda_joint7" type="revolute">
    <origin rpy="1.57079632679 0 0" xyz="0.088 0 0" />
    <parent link="panda_link6" />
    <child link="panda_link7" />
    <axis xyz="0 0 1" />
    <limit effort="12" lower="-2.9671" upper="2.9671" velocity="2.6100" />
  </joint>
  <link name="panda_link8">
    <inertial>
      <origin rpy="0 0 0" xyz="0 0 0" />
      <mass value="0.0" />
      <inertia ixx="0.1" ixy="0" ixz="0" iyy="0.1" iyz="0" izz="0.1" />
    </inertial>
  </link>
  <joint name="panda_joint8" type="fixed">
    <origin rpy="0 0 0" xyz="0 0 0.107" />
    <parent link="panda_link7" />
    <child link="panda_link8" />
    <axis xyz="0 0 1" />
  </joint>
  <joint name="panda_hand_joint" type="fixed">
    <parent link="panda_link8" />
    <child link="panda_hand" />
    <origin rpy="0 0 -0.785398163397" xyz="0 0 0" />
  </joint>
  <link name="panda_hand">
    <inertial>
      <origin rpy="0 0 0" xyz="0 0 0.04" />
      <mass value=".81" />
      <inertia ixx="0.1" ixy="0" ixz="0" iyy="0.1" iyz="0" izz="0.1" />
    </inertial>
    <visual>
      <geometry>
        <mesh filename="meshes/visual/hand.obj" />
      </geometry>
      <material name="panda_white" />
    </visual>
  </link>
  <link name="panda_leftfinger">
    <contact>
      <friction_anchor />
      <stiffness value="30000.0" />
      <damping value="1000.0" />
      <spinning_friction value="0.1" />
      <lateral_friction value="1.0" />
    </contact>
    <inertial>
      <origin rpy="0 0 0" xyz="0 0.01 0.02" />
      <mass value="0.1" />
      <inertia ixx="0.1" ixy="0" ixz="0" iyy="0.1" iyz="0" izz="0.1" />
    </inertial>
    <visual>
      <geometry>
        <mesh filename="meshes/visual/finger.obj" />
      </geometry>
      <material name="panda_white" />
    </visual>
  </link>
  <link name="panda_rightfinger">
    <contact>
      <friction_anchor />
      <stiffness value="30000.0" />
      <damping value="1000.0" />
      <spinning_friction value="0.1" />
      <lateral_friction value="1.0" />
    </contact>
    <inertial>
      <origin rpy="0 0 0" xyz="0 -0.01 0.02" />
      <mass value="0.1" />
      <inertia ixx="0.1" ixy="0" ixz="0" iyy="0.1" iyz="0" izz="0.1" />
    </inertial>
    <visual>
      <origin rpy="0 0 3.14159265359" xyz="0 0 0" />
      <geometry>
        <mesh filename="meshes/visual/finger.obj" />
      </geometry>
      <material name="panda_white" />
    </visual>
  </link>
  <joint name="panda_finger_joint1" type="fixed">
    <parent link="panda_hand" />
    <child link="panda_leftfinger" />
    <origin rpy="0 0 0" xyz="0 0 0.0584" />
    <axis xyz="0 1 0" />
    <limit effort="20" lower="0.0" upper="0.04" velocity="0.2" />
  </joint>
  <joint name="panda_finger_joint2" type="fixed">
    <parent link="panda_hand" />
    <child link="panda_rightfinger" />
    <origin rpy="0 0 0" xyz="0 0 0.0584" />
    <axis xyz="0 -1 0" />
    <limit effort="20" lower="0.0" upper="0.04" velocity="0.2" />
    <mimic joint="panda_finger_joint1" />
  </joint>
  <link name="panda_grasptarget">
    <inertial>
      <origin rpy="0 0 0" xyz="0 0 0" />
      <mass value="0.0" />
      <inertia ixx="0.1" ixy="0" ixz="0" iyy="0.1" iyz="0" izz="0.1" />
    </inertial>
  </link>
  <joint name="panda_grasptarget_hand" type="fixed">
    <parent link="panda_hand" />
    <child link="panda_grasptarget" />
    <origin rpy="0 0 0" xyz="0 0 0.105" />
  </joint>
</robot>
